Traceback (most recent call last):
  File "C:\Users\morishita\AppData\Local\Programs\Python\Python310\lib\site-packages\jupyter_cache\executors\utils.py", line 51, in single_nb_execution
    executenb(
  File "C:\Users\morishita\AppData\Local\Programs\Python\Python310\lib\site-packages\nbclient\client.py", line 1204, in execute
    return NotebookClient(nb=nb, resources=resources, km=km, **kwargs).execute()
  File "C:\Users\morishita\AppData\Local\Programs\Python\Python310\lib\site-packages\nbclient\util.py", line 84, in wrapped
    return just_run(coro(*args, **kwargs))
  File "C:\Users\morishita\AppData\Local\Programs\Python\Python310\lib\site-packages\nbclient\util.py", line 62, in just_run
    return loop.run_until_complete(coro)
  File "C:\Users\morishita\AppData\Local\Programs\Python\Python310\lib\asyncio\base_events.py", line 646, in run_until_complete
    return future.result()
  File "C:\Users\morishita\AppData\Local\Programs\Python\Python310\lib\site-packages\nbclient\client.py", line 663, in async_execute
    await self.async_execute_cell(
  File "C:\Users\morishita\AppData\Local\Programs\Python\Python310\lib\site-packages\nbclient\client.py", line 965, in async_execute_cell
    await self._check_raise_for_error(cell, cell_index, exec_reply)
  File "C:\Users\morishita\AppData\Local\Programs\Python\Python310\lib\site-packages\nbclient\client.py", line 862, in _check_raise_for_error
    raise CellExecutionError.from_cell_and_msg(cell, exec_reply_content)
nbclient.exceptions.CellExecutionError: An error occurred while executing the following cell:
------------------
import numpy as np    # numpyを取り込み、npという名前で使う、という命令
import matplotlib.pyplot as plt
%matplotlib inline

x = np.arange(0, 4 * np.pi, np.pi / 100)
y = np.sin(x)
plt.plot(x, y)   # 折れ線グラフの描画を指示
plt.xlabel("hoge")
plt.ylabel("tako")
plt.title("fuga")
plt.savefig("fig_matplotlib_1.png")
plt.show()       # グラフの表示を指示（グラフの設定が終わった後に呼び出す）
------------------

[1;31m---------------------------------------------------------------------------[0m
[1;31mModuleNotFoundError[0m                       Traceback (most recent call last)
Cell [1;32mIn [1], line 2[0m
[0;32m      1[0m [38;5;28;01mimport[39;00m [38;5;21;01mnumpy[39;00m [38;5;28;01mas[39;00m [38;5;21;01mnp[39;00m    [38;5;66;03m# numpyを取り込み、npという名前で使う、という命令[39;00m
[1;32m----> 2[0m [38;5;28;01mimport[39;00m [38;5;21;01mmatplotlib[39;00m[38;5;21;01m.[39;00m[38;5;21;01mpyplot[39;00m [38;5;28;01mas[39;00m [38;5;21;01mplt[39;00m
[0;32m      3[0m get_ipython()[38;5;241m.[39mrun_line_magic([38;5;124m'[39m[38;5;124mmatplotlib[39m[38;5;124m'[39m, [38;5;124m'[39m[38;5;124minline[39m[38;5;124m'[39m)
[0;32m      5[0m x [38;5;241m=[39m np[38;5;241m.[39marange([38;5;241m0[39m, [38;5;241m4[39m [38;5;241m*[39m np[38;5;241m.[39mpi, np[38;5;241m.[39mpi [38;5;241m/[39m [38;5;241m100[39m)

[1;31mModuleNotFoundError[0m: No module named 'matplotlib'
ModuleNotFoundError: No module named 'matplotlib'

